<?xml version="1.0" encoding="utf-8"?>
<!-- This URDF was automatically created by SolidWorks to URDF Exporter! Originally created by Stephen Brawner (brawner@gmail.com) 
     Commit Version: 1.6.0-1-g15f4949  Build Version: 1.6.7594.29634
     For more information, please see http://wiki.ros.org/sw_urdf_exporter -->
<robot
  name="Prototype_Assem_1">
  <link
    name="base_link">
    <inertial>
      <origin
        xyz="0.0633399432951817 -0.115306777162767 0.0773215092552989"
        rpy="0 0 0" />
      <mass
        value="0.146073009183013" />
      <inertia
        ixx="0.000122971371729359"
        ixy="-2.52315784573037E-20"
        ixz="-2.94043958335381E-22"
        iyy="0.000268350561212543"
        iyz="7.38276631013834E-21"
        izz="0.000388834204788205" />
    </inertial>
    <visual>
      <origin
        xyz="0 0 0"
        rpy="0 0 0" />
      <geometry>
        <mesh
          filename="package://Prototype_Assem_1/meshes/base_link.STL" />
      </geometry>
      <material
        name="">
        <color
          rgba="0.792156862745098 0.819607843137255 0.933333333333333 1" />
      </material>
    </visual>
    <collision>
      <origin
        xyz="0 0 0"
        rpy="0 0 0" />
      <geometry>
        <mesh
          filename="package://Prototype_Assem_1/meshes/base_link.STL" />
      </geometry>
    </collision>
  </link>
  <link
    name="wheel_1_link">
    <inertial>
      <origin
        xyz="-2.08166817117217E-16 0.00500000000000017 1.80411241501588E-16"
        rpy="0 0 0" />
      <mass
        value="0.0191737468916469" />
      <inertia
        ixx="3.14423074657109E-06"
        ixy="-9.90329068367178E-21"
        ixz="6.79865277851786E-36"
        iyy="5.97552557291833E-06"
        iyz="-1.88627595496748E-21"
        izz="3.14423074657109E-06" />
    </inertial>
    <visual>
      <origin
        xyz="0 0 0"
        rpy="0 0 0" />
      <geometry>
        <mesh
          filename="package://Prototype_Assem_1/meshes/wheel_1_link.STL" />
      </geometry>
      <material
        name="">
        <color
          rgba="0.792156862745098 0.819607843137255 0.933333333333333 1" />
      </material>
    </visual>
    <collision>
      <origin
        xyz="0 0 0"
        rpy="0 0 0" />
      <geometry>
        <mesh
          filename="package://Prototype_Assem_1/meshes/wheel_1_link.STL" />
      </geometry>
    </collision>
  </link>
  <joint
    name="wheel_1_"
    type="continuous">
    <origin
      xyz="0.123339943295182 -0.0553067771627669 0.0773215092552989"
      rpy="0 -1.5707963267949 0" />
    <parent
      link="base_link" />
    <child
      link="wheel_1_link" />
    <axis
      xyz="0 1 0" />
  </joint>
  <link
    name="wheel_2_link">
    <inertial>
      <origin
        xyz="-1.38777878078145E-17 -0.00500000000000014 -1.16573417585641E-15"
        rpy="0 0 0" />
      <mass
        value="0.0191737468916469" />
      <inertia
        ixx="3.14423074657109E-06"
        ixy="-3.11535924767132E-37"
        ixz="-1.98766643320901E-36"
        iyy="5.97552557291834E-06"
        iyz="2.34745597615571E-22"
        izz="3.14423074657109E-06" />
    </inertial>
    <visual>
      <origin
        xyz="0 0 0"
        rpy="0 0 0" />
      <geometry>
        <mesh
          filename="package://Prototype_Assem_1/meshes/wheel_2_link.STL" />
      </geometry>
      <material
        name="">
        <color
          rgba="0.792156862745098 0.819607843137255 0.933333333333333 1" />
      </material>
    </visual>
    <collision>
      <origin
        xyz="0 0 0"
        rpy="0 0 0" />
      <geometry>
        <mesh
          filename="package://Prototype_Assem_1/meshes/wheel_2_link.STL" />
      </geometry>
    </collision>
  </link>
  <joint
    name="wheel_2"
    type="continuous">
    <origin
      xyz="0.123339943295182 -0.165306777162768 0.0773215092552989"
      rpy="0 0 0" />
    <parent
      link="base_link" />
    <child
      link="wheel_2_link" />
    <axis
      xyz="0 1 0" />
  </joint>
  <link
    name="wheel_3_link">
    <inertial>
      <origin
        xyz="6.93889390390723E-18 0.005 0"
        rpy="0 0 0" />
      <mass
        value="0.0191737468916469" />
      <inertia
        ixx="3.14423074657109E-06"
        ixy="-1.15737129950298E-22"
        ixz="1.05879118406788E-22"
        iyy="5.97552557291833E-06"
        iyz="8.00270033642477E-23"
        izz="3.14423074657109E-06" />
    </inertial>
    <visual>
      <origin
        xyz="0 0 0"
        rpy="0 0 0" />
      <geometry>
        <mesh
          filename="package://Prototype_Assem_1/meshes/wheel_3_link.STL" />
      </geometry>
      <material
        name="">
        <color
          rgba="0.792156862745098 0.819607843137255 0.933333333333333 1" />
      </material>
    </visual>
    <collision>
      <origin
        xyz="0 0 0"
        rpy="0 0 0" />
      <geometry>
        <mesh
          filename="package://Prototype_Assem_1/meshes/wheel_3_link.STL" />
      </geometry>
    </collision>
  </link>
  <joint
    name="wheel_3_"
    type="continuous">
    <origin
      xyz="0.0033399432951817 -0.0553067771627673 0.0773215092552989"
      rpy="0 -0.60300839646753 3.14159265358979" />
    <parent
      link="base_link" />
    <child
      link="wheel_3_link" />
    <axis
      xyz="0 1 0" />
  </joint>
  <link
    name="wheel_4_link">
    <inertial>
      <origin
        xyz="-6.10622663543836E-16 0.00500000000000014 5.77662917500277E-16"
        rpy="0 0 0" />
      <mass
        value="0.0191737468916469" />
      <inertia
        ixx="3.14423074657109E-06"
        ixy="-9.90329068367179E-21"
        ixz="4.67095572026756E-37"
        iyy="5.97552557291834E-06"
        iyz="-1.1586282522982E-22"
        izz="3.14423074657109E-06" />
    </inertial>
    <visual>
      <origin
        xyz="0 0 0"
        rpy="0 0 0" />
      <geometry>
        <mesh
          filename="package://Prototype_Assem_1/meshes/wheel_4_link.STL" />
      </geometry>
      <material
        name="">
        <color
          rgba="0.792156862745098 0.819607843137255 0.933333333333333 1" />
      </material>
    </visual>
    <collision>
      <origin
        xyz="0 0 0"
        rpy="0 0 0" />
      <geometry>
        <mesh
          filename="package://Prototype_Assem_1/meshes/wheel_4_link.STL" />
      </geometry>
    </collision>
  </link>
  <joint
    name="wheel_4"
    type="continuous">
    <origin
      xyz="0.0033399432951817 -0.165306777162767 0.0773215092552989"
      rpy="0 -1.5707963267949 0" />
    <parent
      link="base_link" />
    <child
      link="wheel_4_link" />
    <axis
      xyz="0 1 0" />
  </joint>
</robot>