<?xml version="1.0" encoding="utf-8"?>
<robot name="full_assembly" xmlns:xacro="http://www.ros.org/wiki/xacro">

<!--xacro:include filename="$(find full_assembly)/urdf/materials.xacro" /> -->
<!--<xacro:include filename="$(find rur_detailed_description)/urdf/rur_detailed.trans" />-->

<xacro:include filename="$(find full_assembly)/gazebo/full_assembly_detailed_materials.gazebo" />
<xacro:include filename="$(find full_assembly)/gazebo/full_assembly_detailed_physics.gazebo" />
<xacro:include filename="$(find full_assembly)/gazebo/full_assembly_detailed_plugins.gazebo" />

  <link
    name="base_link">
    <inertial>
      <origin
        xyz="0.0317697682326636 -2.00626817905836E-05 0.00645830721596166"
        rpy="0 0 0" />
      <mass
        value="0.70453875638497" />
      <inertia
        ixx="0.000379820850960951"
        ixy="-3.26746107078172E-07"
        ixz="-5.85254707328423E-08"
        iyy="0.00037267495162664"
        iyz="3.00888699043317E-07"
        izz="0.000690189876075804" />
    </inertial>
    <visual>
      <origin
        xyz="0 0 0"
        rpy="0 0 0" />
      <geometry>
        <mesh
          filename="package://full_assembly/meshes/base_link.STL" />
      </geometry>
      <material
        name="">
        <color
          rgba="0.792156862745098 0.819607843137255 0.933333333333333 1" />
      </material>
    </visual>
    <collision>
      <origin
        xyz="0 0 0"
        rpy="0 0 0" />
      <geometry>
        <mesh
          filename="package://full_assembly/meshes/base_link.STL" />
      </geometry>
    </collision>
  </link>
  <link
    name="right_front">
    <inertial>
      <origin
        xyz="-5.55111512312578E-17 0.0116195706084418 -5.55111512312578E-17"
        rpy="0 0 0" />
      <mass
        value="0.0480575201994131" />
      <inertia
        ixx="1.66694167765259E-05"
        ixy="8.54982718520615E-21"
        ixz="5.82361746292034E-17"
        iyy="2.78746883020904E-05"
        iyz="-3.07816725160037E-21"
        izz="1.6669416776531E-05" />
    </inertial>
    <visual>
      <origin
        xyz="0 0 0"
        rpy="0 0 0" />
      <geometry>
        <mesh
          filename="package://full_assembly/meshes/right_front.STL" />
      </geometry>
      <material
        name="">
        <color
          rgba="0.298039215686275 0.298039215686275 0.298039215686275 1" />
      </material>
    </visual>
    <collision>
      <origin
        xyz="0 0 0"
        rpy="0 0 0" />
      <geometry>
        <mesh
          filename="package://full_assembly/meshes/right_front.STL" />
      </geometry>
    </collision>
  </link>
  <joint
    name="right_front_joint"
    type="continuous">
    <origin
      xyz="0.105 -0.12808 -0.019"
      rpy="0 0 0" />
    <parent
      link="base_link" />
    <child
      link="right_front" />
    <axis
      xyz="0 1 0" />
  </joint>
  <link
    name="left_front">
    <inertial>
      <origin
        xyz="0 -0.0116195706084417 0"
        rpy="0 0 0" />
      <mass
        value="0.0480575201994126" />
      <inertia
        ixx="1.66694167765259E-05"
        ixy="1.65585172550371E-20"
        ixz="-5.82291127011538E-17"
        iyy="2.78746883020902E-05"
        iyz="3.77553780942202E-21"
        izz="1.66694167765308E-05" />
    </inertial>
    <visual>
      <origin
        xyz="0 0 0"
        rpy="0 0 0" />
      <geometry>
        <mesh
          filename="package://full_assembly/meshes/left_front.STL" />
      </geometry>
      <material
        name="">
        <color
          rgba="0.298039215686275 0.298039215686275 0.298039215686275 1" />
      </material>
    </visual>
    <collision>
      <origin
        xyz="0 0 0"
        rpy="0 0 0" />
      <geometry>
        <mesh
          filename="package://full_assembly/meshes/left_front.STL" />
      </geometry>
    </collision>
  </link>
  <joint
    name="left_front_joint"
    type="continuous">
    <origin
      xyz="0.105 0.12808 -0.019"
      rpy="0 0 0" />
    <parent
      link="base_link" />
    <child
      link="left_front" />
    <axis
      xyz="0 1 0" />
  </joint>
  <link
    name="left_back">
    <inertial>
      <origin
        xyz="2.68068987147041E-17 -0.0116195706084418 8.32667268468867E-17"
        rpy="0 0 0" />
      <mass
        value="0.0480575201994128" />
      <inertia
        ixx="1.66694167765308E-05"
        ixy="-3.55601380562635E-21"
        ixz="5.82083066749743E-17"
        iyy="2.78746883020903E-05"
        iyz="2.89822351885368E-21"
        izz="1.66694167765258E-05" />
    </inertial>
    <visual>
      <origin
        xyz="0 0 0"
        rpy="0 0 0" />
      <geometry>
        <mesh
          filename="package://full_assembly/meshes/left_back.STL" />
      </geometry>
      <material
        name="">
        <color
          rgba="0.2 0.4 0.698039215686274 1" />
      </material>
    </visual>
    <collision>
      <origin
        xyz="0 0 0"
        rpy="0 0 0" />
      <geometry>
        <mesh
          filename="package://full_assembly/meshes/left_back.STL" />
      </geometry>
    </collision>
  </link>
  <joint
    name="left_back_joint"
    type="continuous">
    <origin
      xyz="-0.105 0.12808 -0.019"
      rpy="0 0 0" />
    <parent
      link="base_link" />
    <child
      link="left_back" />
    <axis
      xyz="0 1 0" />
  </joint>
  <link
    name="right_back">
    <inertial>
      <origin
        xyz="2.7376104855259E-18 0.0116195706084418 8.32667268468867E-17"
        rpy="0 0 0" />
      <mass
        value="0.0480575201994127" />
      <inertia
        ixx="1.66694167765308E-05"
        ixy="2.15306910399576E-21"
        ixz="-5.82717086699064E-17"
        iyy="2.78746883020902E-05"
        iyz="-2.64947574013677E-21"
        izz="1.66694167765258E-05" />
    </inertial>
    <visual>
      <origin
        xyz="0 0 0"
        rpy="0 0 0" />
      <geometry>
        <mesh
          filename="package://full_assembly/meshes/right_back.STL" />
      </geometry>
      <material
        name="">
        <color
          rgba="0.298039215686275 0.298039215686275 0.298039215686275 1" />
      </material>
    </visual>
    <collision>
      <origin
        xyz="0 0 0"
        rpy="0 0 0" />
      <geometry>
        <mesh
          filename="package://full_assembly/meshes/right_back.STL" />
      </geometry>
    </collision>
  </link>
  <joint
    name="right_back_joint"
    type="continuous">
    <origin
      xyz="-0.105 -0.12808 -0.019"
      rpy="0 0 0" />
    <parent
      link="base_link" />
    <child
      link="right_back" />
    <axis
      xyz="0 1 0" />
  </joint>
  <link
    name="rp_lidar">
    <inertial>
      <origin
        xyz="0.00676653011666359 -0.00020782756685464 -0.0224318722671598"
        rpy="0 0 0" />
      <mass
        value="1.33076913637071" />
      <inertia
        ixx="0.00061491794045409"
        ixy="-8.01984318975188E-07"
        ixz="0.00015824302591117"
        iyy="0.000960697335617223"
        iyz="-3.09162986587582E-06"
        izz="0.00109815200027136" />
    </inertial>
    <visual>
      <origin
        xyz="0 0 0"
        rpy="0 0 0" />
      <geometry>
        <mesh
          filename="package://full_assembly/meshes/rp_lidar.STL" />
      </geometry>
      <material
        name="">
        <color
          rgba="0.529411764705882 0.549019607843137 0.549019607843137 1" />
      </material>
    </visual>
    <collision>
      <origin
        xyz="0 0 0"
        rpy="0 0 0" />
      <geometry>
        <mesh
          filename="package://full_assembly/meshes/rp_lidar.STL" />
      </geometry>
    </collision>
  </link>
  <joint
    name="rp_lidar_joint"
    type="fixed">
    <origin
      xyz="0.041696 0.0026159 0.1117"
      rpy="0 0 0" />
    <parent
      link="base_link" />
    <child
      link="rp_lidar" />
    <axis
      xyz="0 0 0" />
  </joint>
</robot>